Workbook

Sheet Summary
A1: Topic assignment review | B1: Topic assignment review | C1: Topic assignment review | D1: Topic assignment review | E1: Topic assignment review | F1: Topic assignment review | G1: Topic assignment review | H1: Topic assignment review
A2: Scope: 135 selected model–complaint pairs, covering 118 complaint IDs. The model log reports 1,200,000 training rows and 1,000 evaluated rows per model. | B2: Scope: 135 selected model–complaint pairs, covering 118 complaint IDs. The model log reports 1,200,000 training rows and 1,000 evaluated rows per model. | C2: Scope: 135 selected model–complaint pairs, covering 118 complaint IDs. The model log reports 1,200,000 training rows and 1,000 evaluated rows per model. | D2: Scope: 135 selected model–complaint pairs, covering 118 complaint IDs. The model log reports 1,200,000 training rows and 1,000 evaluated rows per model. | E2: Scope: 135 selected model–complaint pairs, covering 118 complaint IDs. The model log reports 1,200,000 training rows and 1,000 evaluated rows per model. | F2: Scope: 135 selected model–complaint pairs, covering 118 complaint IDs. The model log reports 1,200,000 training rows and 1,000 evaluated rows per model. | G2: Scope: 135 selected model–complaint pairs, covering 118 complaint IDs. The model log reports 1,200,000 training rows and 1,000 evaluated rows per model. | H2: Scope: 135 selected model–complaint pairs, covering 118 complaint IDs. The model log reports 1,200,000 training rows and 1,000 evaluated rows per model.
A4: Model | B4: Reviewed | C4: Yes | D4: No | E4: Unclear | F4: Yes = a reasonable fit to the main issue or a clearly matching template. | G4: Yes = a reasonable fit to the main issue or a clearly matching template. | H4: Yes = a reasonable fit to the main issue or a clearly matching template.
A5: LSA | B5: =COUNTIF(Review!$A$5:$A$139,A5) -> 27 | C5: =COUNTIFS(Review!$A$5:$A$139,A5,Review!$D$5:$D$139,"Yes") -> 27 | D5: =COUNTIFS(Review!$A$5:$A$139,A5,Review!$D$5:$D$139,"No") -> 0 | E5: =COUNTIFS(Review!$A$5:$A$139,A5,Review!$D$5:$D$139,"Unclear") -> 0 | F5: Yes = a reasonable fit to the main issue or a clearly matching template. | G5: Yes = a reasonable fit to the main issue or a clearly matching template. | H5: Yes = a reasonable fit to the main issue or a clearly matching template.
A6: LDA | B6: =COUNTIF(Review!$A$5:$A$139,A6) -> 36 | C6: =COUNTIFS(Review!$A$5:$A$139,A6,Review!$D$5:$D$139,"Yes") -> 30 | D6: =COUNTIFS(Review!$A$5:$A$139,A6,Review!$D$5:$D$139,"No") -> 1 | E6: =COUNTIFS(Review!$A$5:$A$139,A6,Review!$D$5:$D$139,"Unclear") -> 5 | F6: No = only a partial match; the main issue is missed. | G6: No = only a partial match; the main issue is missed. | H6: No = only a partial match; the main issue is missed.
A7: BERTopic | B7: =COUNTIF(Review!$A$5:$A$139,A7) -> 36 | C7: =COUNTIFS(Review!$A$5:$A$139,A7,Review!$D$5:$D$139,"Yes") -> 29 | D7: =COUNTIFS(Review!$A$5:$A$139,A7,Review!$D$5:$D$139,"No") -> 4 | E7: =COUNTIFS(Review!$A$5:$A$139,A7,Review!$D$5:$D$139,"Unclear") -> 3 | F7: No = only a partial match; the main issue is missed. | G7: No = only a partial match; the main issue is missed. | H7: No = only a partial match; the main issue is missed.
A8: NMF | B8: =COUNTIF(Review!$A$5:$A$139,A8) -> 36 | C8: =COUNTIFS(Review!$A$5:$A$139,A8,Review!$D$5:$D$139,"Yes") -> 35 | D8: =COUNTIFS(Review!$A$5:$A$139,A8,Review!$D$5:$D$139,"No") -> 0 | E8: =COUNTIFS(Review!$A$5:$A$139,A8,Review!$D$5:$D$139,"Unclear") -> 1 | F8: Unclear = too little complaint detail or an unclear topic. | G8: Unclear = too little complaint detail or an unclear topic. | H8: Unclear = too little complaint detail or an unclear topic.
A9: Total | B9: =SUM(B5:B8) -> 135 | C9: =SUM(C5:C8) -> 121 | D9: =SUM(D5:D8) -> 5 | E9: =SUM(E5:E8) -> 9 | F9: Unclear = too little complaint detail or an unclear topic. | G9: Unclear = too little complaint detail or an unclear topic. | H9: Unclear = too little complaint detail or an unclear topic.
A11: What the judgements mean | B11: What the judgements mean | C11: What the judgements mean | D11: What the judgements mean | E11: What the judgements mean | F11: What the judgements mean | G11: What the judgements mean | H11: What the judgements mean
A12: Assessment | B12: Count | C12: Fit? | D12: Rule used in this review | E12: Rule used in this review | F12: Rule used in this review | G12: Rule used in this review | H12: Rule used in this review
A13: Clear fit | B13: =COUNTIF(Review!$E$5:$E$139,A13) -> 83 | C13: Yes | D13: The complaint explicitly describes the issue represented by the distinctive topic terms. | E13: The complaint explicitly describes the issue represented by the distinctive topic terms. | F13: The complaint explicitly describes the issue represented by the distinctive topic terms. | G13: The complaint explicitly describes the issue represented by the distinctive topic terms. | H13: The complaint explicitly describes the issue represented by the distinctive topic terms.
A14: Broad fit | B14: =COUNTIF(Review!$E$5:$E$139,A14) -> 19 | C14: Yes | D14: The main issue falls within the theme, but the topic misses useful detail or mixes several issues. | E14: The main issue falls within the theme, but the topic misses useful detail or mixes several issues. | F14: The main issue falls within the theme, but the topic misses useful detail or mixes several issues. | G14: The main issue falls within the theme, but the topic misses useful detail or mixes several issues. | H14: The main issue falls within the theme, but the topic misses useful detail or mixes several issues.
A15: Template fit | B15: =COUNTIF(Review!$E$5:$E$139,A15) -> 19 | C15: Yes | D15: The repeated letter or statutory wording matches; this does not prove a separate substantive issue. | E15: The repeated letter or statutory wording matches; this does not prove a separate substantive issue. | F15: The repeated letter or statutory wording matches; this does not prove a separate substantive issue. | G15: The repeated letter or statutory wording matches; this does not prove a separate substantive issue. | H15: The repeated letter or statutory wording matches; this does not prove a separate substantive issue.
A16: Partial fit | B16: =COUNTIF(Review!$E$5:$E$139,A16) -> 5 | C16: No | D16: Some words or product terms match, but the central problem is not captured well. | E16: Some words or product terms match, but the central problem is not captured well. | F16: Some words or product terms match, but the central problem is not captured well. | G16: Some words or product terms match, but the central problem is not captured well. | H16: Some words or product terms match, but the central problem is not captured well.
A17: Insufficient text | B17: =COUNTIF(Review!$E$5:$E$139,A17) -> 3 | C17: Unclear | D17: The complaint supplies too little context to establish its fit. | E17: The complaint supplies too little context to establish its fit. | F17: The complaint supplies too little context to establish its fit. | G17: The complaint supplies too little context to establish its fit. | H17: The complaint supplies too little context to establish its fit.
A18: Topic unclear | B18: =COUNTIF(Review!$E$5:$E$139,A18) -> 6 | C18: Unclear | D18: The supplied keywords do not define a stable issue clearly enough to judge. | E18: The supplied keywords do not define a stable issue clearly enough to judge. | F18: The supplied keywords do not define a stable issue clearly enough to judge. | G18: The supplied keywords do not define a stable issue clearly enough to judge. | H18: The supplied keywords do not define a stable issue clearly enough to judge.
A20: Main findings | B20: Main findings | C20: Main findings | D20: Main findings | E20: Main findings | F20: Main findings | G20: Main findings | H20: Main findings
A21: The clearest examples concern late-payment errors, debt validation/collection, identity theft and unauthorized inquiries. See the individual reasons in Review. | B21: The clearest examples concern late-payment errors, debt validation/collection, identity theft and unauthorized inquiries. See the individual reasons in Review. | C21: The clearest examples concern late-payment errors, debt validation/collection, identity theft and unauthorized inquiries. See the individual reasons in Review. | D21: The clearest examples concern late-payment errors, debt validation/collection, identity theft and unauthorized inquiries. See the individual reasons in Review. | E21: The clearest examples concern late-payment errors, debt validation/collection, identity theft and unauthorized inquiries. See the individual reasons in Review. | F21: The clearest examples concern late-payment errors, debt validation/collection, identity theft and unauthorized inquiries. See the individual reasons in Review. | G21: The clearest examples concern late-payment errors, debt validation/collection, identity theft and unauthorized inquiries. See the individual reasons in Review. | H21: The clearest examples concern late-payment errors, debt validation/collection, identity theft and unauthorized inquiries. See the individual reasons in Review.
A22: Several topics mainly capture repeated statutory letters: LSA C2+, LDA T11, BERTopic B4 and NMF N2. NMF N8 and N9 also contain closely repeated templates. | B22: Several topics mainly capture repeated statutory letters: LSA C2+, LDA T11, BERTopic B4 and NMF N2. NMF N8 and N9 also contain closely repeated templates. | C22: Several topics mainly capture repeated statutory letters: LSA C2+, LDA T11, BERTopic B4 and NMF N2. NMF N8 and N9 also contain closely repeated templates. | D22: Several topics mainly capture repeated statutory letters: LSA C2+, LDA T11, BERTopic B4 and NMF N2. NMF N8 and N9 also contain closely repeated templates. | E22: Several topics mainly capture repeated statutory letters: LSA C2+, LDA T11, BERTopic B4 and NMF N2. NMF N8 and N9 also contain closely repeated templates. | F22: Several topics mainly capture repeated statutory letters: LSA C2+, LDA T11, BERTopic B4 and NMF N2. NMF N8 and N9 also contain closely repeated templates. | G22: Several topics mainly capture repeated statutory letters: LSA C2+, LDA T11, BERTopic B4 and NMF N2. NMF N8 and N9 also contain closely repeated templates. | H22: Several topics mainly capture repeated statutory letters: LSA C2+, LDA T11, BERTopic B4 and NMF N2. NMF N8 and N9 also contain closely repeated templates.
A23: Five assignments are partial matches: review rows 44, 65, 66, 70 and 94. Examples include a name-spelling error in an inquiry topic and identity theft in a student-loan topic. | B23: Five assignments are partial matches: review rows 44, 65, 66, 70 and 94. Examples include a name-spelling error in an inquiry topic and identity theft in a student-loan topic. | C23: Five assignments are partial matches: review rows 44, 65, 66, 70 and 94. Examples include a name-spelling error in an inquiry topic and identity theft in a student-loan topic. | D23: Five assignments are partial matches: review rows 44, 65, 66, 70 and 94. Examples include a name-spelling error in an inquiry topic and identity theft in a student-loan topic. | E23: Five assignments are partial matches: review rows 44, 65, 66, 70 and 94. Examples include a name-spelling error in an inquiry topic and identity theft in a student-loan topic. | F23: Five assignments are partial matches: review rows 44, 65, 66, 70 and 94. Examples include a name-spelling error in an inquiry topic and identity theft in a student-loan topic. | G23: Five assignments are partial matches: review rows 44, 65, 66, 70 and 94. Examples include a name-spelling error in an inquiry topic and identity theft in a student-loan topic. | H23: Five assignments are partial matches: review rows 44, 65, 66, 70 and 94. Examples include a name-spelling error in an inquiry topic and identity theft in a student-loan topic.
A24: Two keyword sets are too vague to interpret confidently: LDA T12 and BERTopic B1. The account-number fragment (document 666137) is unassessable in both LDA and NMF. | B24: Two keyword sets are too vague to interpret confidently: LDA T12 and BERTopic B1. The account-number fragment (document 666137) is unassessable in both LDA and NMF. | C24: Two keyword sets are too vague to interpret confidently: LDA T12 and BERTopic B1. The account-number fragment (document 666137) is unassessable in both LDA and NMF. | D24: Two keyword sets are too vague to interpret confidently: LDA T12 and BERTopic B1. The account-number fragment (document 666137) is unassessable in both LDA and NMF. | E24: Two keyword sets are too vague to interpret confidently: LDA T12 and BERTopic B1. The account-number fragment (document 666137) is unassessable in both LDA and NMF. | F24: Two keyword sets are too vague to interpret confidently: LDA T12 and BERTopic B1. The account-number fragment (document 666137) is unassessable in both LDA and NMF. | G24: Two keyword sets are too vague to interpret confidently: LDA T12 and BERTopic B1. The account-number fragment (document 666137) is unassessable in both LDA and NMF. | H24: Two keyword sets are too vague to interpret confidently: LDA T12 and BERTopic B1. The account-number fragment (document 666137) is unassessable in both LDA and NMF.
A25: LSA assigns 712 of the 1,000 held-out complaints to C1+. Good fits among its selected examples do not resolve that broad-topic concentration or prove good separation. | B25: LSA assigns 712 of the 1,000 held-out complaints to C1+. Good fits among its selected examples do not resolve that broad-topic concentration or prove good separation. | C25: LSA assigns 712 of the 1,000 held-out complaints to C1+. Good fits among its selected examples do not resolve that broad-topic concentration or prove good separation. | D25: LSA assigns 712 of the 1,000 held-out complaints to C1+. Good fits among its selected examples do not resolve that broad-topic concentration or prove good separation. | E25: LSA assigns 712 of the 1,000 held-out complaints to C1+. Good fits among its selected examples do not resolve that broad-topic concentration or prove good separation. | F25: LSA assigns 712 of the 1,000 held-out complaints to C1+. Good fits among its selected examples do not resolve that broad-topic concentration or prove good separation. | G25: LSA assigns 712 of the 1,000 held-out complaints to C1+. Good fits among its selected examples do not resolve that broad-topic concentration or prove good separation. | H25: LSA assigns 712 of the 1,000 held-out complaints to C1+. Good fits among its selected examples do not resolve that broad-topic concentration or prove good separation.

Sheet Review
A1: Complaint-topic review | B1: Complaint-topic review | C1: Complaint-topic review | D1: Complaint-topic review | E1: Complaint-topic review | F1: Complaint-topic review | G1: Complaint-topic review | H1: Complaint-topic review | I1: Complaint-topic review | J1: Complaint-topic review | K1: Complaint-topic review | L1: Complaint-topic review
A2: Filter Fit? for No or Unclear. Yes includes clear, broad and template fits. The full complaint is in Complaints; the final column gives its first worksheet row. | B2: Filter Fit? for No or Unclear. Yes includes clear, broad and template fits. The full complaint is in Complaints; the final column gives its first worksheet row. | C2: Filter Fit? for No or Unclear. Yes includes clear, broad and template fits. The full complaint is in Complaints; the final column gives its first worksheet row. | D2: Filter Fit? for No or Unclear. Yes includes clear, broad and template fits. The full complaint is in Complaints; the final column gives its first worksheet row. | E2: Filter Fit? for No or Unclear. Yes includes clear, broad and template fits. The full complaint is in Complaints; the final column gives its first worksheet row. | F2: Filter Fit? for No or Unclear. Yes includes clear, broad and template fits. The full complaint is in Complaints; the final column gives its first worksheet row. | G2: Filter Fit? for No or Unclear. Yes includes clear, broad and template fits. The full complaint is in Complaints; the final column gives its first worksheet row. | H2: Filter Fit? for No or Unclear. Yes includes clear, broad and template fits. The full complaint is in Complaints; the final column gives its first worksheet row. | I2: Filter Fit? for No or Unclear. Yes includes clear, broad and template fits. The full complaint is in Complaints; the final column gives its first worksheet row. | J2: Filter Fit? for No or Unclear. Yes includes clear, broad and template fits. The full complaint is in Complaints; the final column gives its first worksheet row. | K2: Filter Fit? for No or Unclear. Yes includes clear, broad and template fits. The full complaint is in Complaints; the final column gives its first worksheet row. | L2: Filter Fit? for No or Unclear. Yes includes clear, broad and template fits. The full complaint is in Complaints; the final column gives its first worksheet row.
A4: Model | B4: Topic | C4: Document ID | D4: Fit? | E4: Assessment | F4: Reviewer notes | G4: Complaint excerpt (first 330 characters) | H4: Interpreted topic theme | I4: Original model label | J4: Original model score | K4: Source review row | L4: Full text starts at row
A5: LSA | B5: C1+ | C5: 1238069 | D5: Yes | E5: Broad fit | F5: The complaint concerns fraudulent inquiries and credit-report corrections. This fits the broad credit-reporting component, but the label does not distinguish identity theft from other reporting problems. | G5: Hi I am submitting this this is not any influence and this is not a third party. has low and unfair credit number for me in their report. I have complained more than 88 times nonstop this is exhausting im they are not putting these fraudulent inquiries in dispute and accounts and they still have not deleted them either I am depr … | H5: Credit reporting and account information (broad) | I5: Component 1, + pole | J5: 0.66710144 | K5: 1 | L5: 6
A6: LSA | B6: C1+ | C6: 383422 | D6: Yes | E6: Broad fit | F6: The consumer disputes an account's open/closed status, late-payment reporting and balances. Credit-reporting accuracy fits, although this component is very broad. | G6: I am completely appalled and disgusted at the fact that your company is willing reporting unverifiable and inaccurate information on my credit report even after the alleged account was disputed multiple times. There is a alleged charged off account that has been reporting inaccurately since the time the alleged account was charg … | H6: Credit reporting and account information (broad) | I6: Component 1, + pole | J6: 0.51055723 | K6: 2 | L6: 13
A7: LSA | B7: C1+ | C7: 211435 | D7: Yes | E7: Broad fit | F7: The complaint challenges reported dates and seeks investigation or removal. This fits credit-reporting accuracy, with substantial legal-template wording. | G7: The credit bureaus stated my account was properly investigated but how is that possible if the open date is inaccurate, the date last active is inaccurate, and date last reported is not accurate. This the ground for removal they also violated my rights under 15 U.S.C. 1681 section 602 A. states I have the right to privacy. 15 U. … | H7: Credit reporting and account information (broad) | I7: Component 1, + pole | J7: 0.49900654 | K7: 3 | L7: 17
A8: LSA | B8: C2+ | C8: 1260106 | D8: Yes | E8: Template fit | F8: The text repeats privacy and written-instruction claims under the FCRA. The statutory keywords match closely; this is a writing-template theme rather than a specific product problem. | G8: In accordance with the Fair Credit Reporting act . , , has violated my rights. 15 U.S.C 1681 section 602 A. States I have the right to privacy. 15 U.S.C 1681 Section 604 A Section 2 : It also states a consumer reporting agency can not furnish a account without my written instructions. | H8: FCRA privacy and written-consent template | I8: Component 2, + pole | J8: 0.81526738 | K8: 4 | L8: 20
A9: LSA | B9: C2+ | C9: 256515 | D9: Yes | E9: Template fit | F9: The privacy and written-instruction letter matches the legal-rights keywords. It closely resembles the other examples in this topic, limiting the variety demonstrated. | G9: In accordance with the Fair Credit Reporting Act, * has violated my rights. 15 U.S.C 1681 section 602 A. states that I have the right to privacy. 15 U.S.C 1681 Section 604 A. Section 2 : It also states that a consumer reporting agency can not furnish an account without my written instructions. | H9: FCRA privacy and written-consent template | I9: Component 2, + pole | J9: 0.81526738 | K9: 5 | L9: 21
A10: LSA | B10: C2+ | C10: 731483 | D10: Yes | E10: Template fit | F10: The complaint uses the same FCRA privacy and consent template as the other examples. The wording fits, but does not demonstrate a distinct financial issue. | G10: In accordance with the Fair Credit Reporting Act has violated my rights. 15 U.S.C. 1681 section 602 A. states I have the rights to privacy. 15 U.S.C. 1681 section 604 A section : It also states a consumer reporting agency can not furnish an account without my written instruction. | H10: FCRA privacy and written-consent template | I10: Component 2, + pole | J10: 0.81526738 | K10: 6 | L10: 22
A11: LSA | B11: C3+ | C11: 1027224 | D11: Yes | E11: Clear fit | F11: The consumer explicitly disputes incorrect items on a credit report. This directly matches the component's inaccurate-information and removal terms. | G11: I have filed a dispute in regards to the incorrect items on my credit report. Information is inaccurate on report | H11: Credit-report corrections and identity theft | I11: Component 3, + pole | J11: 0.38671315 | K11: 7 | L11: 23
A12: LSA | B12: C3+ | C12: 419876 | D12: Yes | E12: Clear fit | F12: The consumer reports identity theft and requests deletion of disputed credit entries using an FTC affidavit. Both the identity-theft and report-correction terms fit. | G12: I am writing to delete the following information in my file. The items I need to delete are listed in the report. I am a victim of identity theft. I ask that the item be deleted to correct my credit report. I reported the theft of my identity to the federal trade commission and I also have enclosed copies of the federal trade co … | H12: Credit-report corrections and identity theft | I12: Component 3, + pole | J12: 0.31539449 | K12: 8 | L12: 24
A13: LSA | B13: C3+ | C13: 518978 | D13: Yes | E13: Clear fit | F13: The complaint asks for removal of credit items linked to identity theft. This matches the keywords, although its template resembles another selected example. | G13: " I am writing to delete the following information in my file. The items I need deleted are listed in the report. I am a victim of identity theft and did not make the charge. I ask that the items be deleted to correct my credit report. I reported the theft of my identity to the Federal Trade Commission and I also have enclosed c … | H13: Credit-report corrections and identity theft | I13: Component 3, + pole | J13: 0.29078749 | K13: 9 | L13: 25
A14: LSA | B14: C3- | C14: 571978 | D14: Yes | E14: Clear fit | F14: The mortgage servicer allegedly misapplied or reversed payments, then demanded arrears and fees. Loan servicing and payment problems are central to this component. | G14: My complaint is about , formerly named , also part of Shellpoint Mortgage Servicing. On my / / statement, I was told to pay a partial payment of my usual monthly mortgage. My usual payment is {$1400.00} per month. My statement said to pay {$370.00}, as a {$1000.00} payment had already been applied. I paid {$400.00} for my statem … | H14: Loan servicing and payment problems | I14: Component 3, - pole | J14: 0.3386516 | K14: 10 | L14: 26
A15: LSA | B15: C3- | C15: 1264038 | D15: Yes | E15: Broad fit | F15: Student-loan payments and forgiveness counts were allegedly misapplied. The broad loan/payment theme fits, although it does not identify student-loan forgiveness specifically. | G15: A student loan was taken out in of for an add on degree. -Graduated in summer -went back to school in Spring -graduated in / / The total amount borrowed was {$34000.00} According to my records/bank statements and payment history, we have paid {$64000.00} towards the loan. {$17000.00} was forgiven with teacher loan forgiveness pr … | H15: Loan servicing and payment problems | I15: Component 3, - pole | J15: 0.32960436 | K15: 11 | L15: 29
A16: LSA | B16: C3- | C16: 533988 | D16: Yes | E16: Clear fit | F16: The complaint describes mortgage-payment handling, escrow or insurance errors and delinquency after a servicing transfer. These are direct loan-servicing and payment issues. | G16: The service provider is Bayview loan services. They purchased my mortgage from in / / . In / / they sent me a welcome letter and an invoice in the amounts of {$5700.00}. My monthly payment on my mortgage has always been {$1600.00} per month ( I have a fixed 30 years mortgage ). All of a sudden I was received this large bill for … | H16: Loan servicing and payment problems | I16: Component 3, - pole | J16: 0.31592542 | K16: 12 | L16: 32
... A67: LDA | B67: T9 | C67: 316293 | D67: Yes | E67: Clear fit | F67: The consumer says TransUnion did not answer disputes about an education account and asks for removal. The report/letter/deletion theme fits. | G67: This is , who is submitting this CFPB complaint myself, and to inform you that there is no third party involved in the process. I sent letters to TransUnion Credit Bureau the date of the last letter was on 2021. And now we are in the month of 2021 and still nothing from them. That means TransUnion has NOT complied with the FairC … | H67: Credit-report disputes and deletion requests | I67: Topic 9 | J67: 0.97708273 | K67: 63 | L67: 97
A68: BERTopic | B68: B0 | C68: 1000280 | D68: Yes | E68: Clear fit | F68: The consumer reports unauthorized use of personal information and unfamiliar credit inquiries. The inquiry-focused topic fits the complaint. | G68: My personal information was used without my knowledge and because of several phone calls from creditors that did not belong to me, that prompted me to check my credit. Upon checking my credit, I have noticed that there are several inquiries and credit accounts that were not requested by me were listed on my credit report. | H68: Credit inquiries and their report/score effects | I68: Online BERTopic cluster 0 | K68: 64 | L68: 98
A69: BERTopic | B69: B0 | C69: 1006349 | D69: No | E69: Partial fit | F69: The complaint is about a misspelled name on a credit report. It shares generic reporting words, but does not concern the topic's distinctive credit-inquiry theme. | G69: I looked at my credit report today and it has my name on there mispelled. | H69: Credit inquiries and their report/score effects | I69: Online BERTopic cluster 0 | K69: 65 | L69: 99
A70: BERTopic | B70: B0 | C70: 1008339 | D70: No | E70: Partial fit | F70: The consumer seeks goodwill removal of historical delinquencies affecting loan access. This is a payment-history/reporting issue rather than a hard-inquiry issue; B9 would be a plausible alternative to inspect. | G70: My credit reports have three Negative connotations. They are defined as : serious delinquency.They happened in 2012, when I was a new immigrant, and I did not know about the country 's credit system. The three accounts about because of events in life, I live in the United States at that time, my father is years old living in , h … | H70: Credit inquiries and their report/score effects | I70: Online BERTopic cluster 0 | K70: 66 | L70: 100
A71: BERTopic | B71: B1 | C71: 1003545 | D71: Unclear | E71: Topic unclear | F71: The consumer received an unsolicited U.S. Bank ReliaCard. B1's generic account, number, information and phone terms do not identify a clear enough issue to judge this assignment confidently. | G71: received us bank reliacard which I never requested. Carb number | H71: Unclear: generic account and contact terms | I71: Online BERTopic cluster 1 | K71: 67 | L71: 102
A72: BERTopic | B72: B1 | C72: 1007823 | D72: Unclear | E72: Topic unclear | F72: The text describes someone using information to obtain accounts. Identity theft is clear, but B1's generic account/contact terms leave its intended subject unclear; B11 is worth inspecting. | G72: Someone used information to obtain account # on / / , account on / / , account # on / / | H72: Unclear: generic account and contact terms | I72: Online BERTopic cluster 1 | K72: 68 | L72: 103
A73: BERTopic | B73: B1 | C73: 1008096 | D73: Unclear | E73: Topic unclear | F73: The consumer questions how accounts were verified and requests removal after no answer. B1's generic account/contact keywords are too vague to judge confidently; B5 is a plausible alternative. | G73: I have inquired multiple times with the company to verify HOW DID THEY VERIFY the accounts in question. I have asked whom did they speak with to verify the accounts along with other questions and the could not verify that they legally verified the accounts. I had asked if they could not tell me how they legally verified the acco … | H73: Unclear: generic account and contact terms | I73: Online BERTopic cluster 1 | K73: 69 | L73: 104
A74: BERTopic | B74: B10 | C74: 1007505 | D74: No | E74: Partial fit | F74: The complaint mainly concerns a closed card account, payment handling and disputed balances or fees. The bank/deposit/transfer theme only partly fits; the card-focused B6 is a plausible alternative. | G74: I closed this account on as this bank gave my Daughter a card on my account in but in they refused to add my wife to the account the whole bill owed is my daughters debt none of it is mine I made a payment to catch account up of this paid it up thru / / these is were the fun begins see on / / my credit report should balance of t … | H74: Bank accounts, deposits, transfers and funds | I74: Online BERTopic cluster 10 | K74: 70 | L74: 105
A75: BERTopic | B75: B10 | C75: 1026633 | D75: Yes | E75: Clear fit | F75: A transfer between accounts allegedly triggered a fraud hold and frozen savings. Bank transfers, funds and account access fit the topic directly. | G75: On / / I transferred a total of {$6000.00} from my joint savings into my personal checking. This had been discussed between both account holders. The following day the person I shared my joint checking and savings account with filed a fraud claim and closed both accounts. Shortly after Bank of America put a {$880000.00} freeze o … | H75: Bank accounts, deposits, transfers and funds | I75: Online BERTopic cluster 10 | K75: 71 | L75: 108
A76: BERTopic | B76: B10 | C76: 1078181 | D76: Yes | E76: Broad fit | F76: The consumer alleges that a bank employee disclosed savings-account balances to a spouse. The bank/account theme fits broadly, but the specific privacy issue is not captured by the main keywords. | G76: I would deposit large sums of my paycheck into this account to save money for future bills or purchases and also as an emergency fund. Nobody was on the account or authorized to access this account. It was in my name only and until an employee, , while working as an employee of TD Bank had given my account information and balanc … | H76: Bank accounts, deposits, transfers and funds | I76: Online BERTopic cluster 10 | K76: 72 | L76: 110
A77: BERTopic | B77: B11 | C77: 1002478 | D77: Yes | E77: Clear fit | F77: The consumer denies knowing a collection account and requests its removal. Disputed account ownership and deletion fit the topic. | G77: I was shocked when I reviewed my credit report and found collection account on my credit report. I am not sure how this happened, but this is a total violations of FCRA and FDCPA, and under these provisions I demand that this account be removed from my credit file as I never had any type of relationship with this company or any … | H77: Fraudulent or unrecognized credit entries | I77: Online BERTopic cluster 11 | K77: 73 | L77: 111
A78: BERTopic | B78: B11 | C78: 1006538 | D78: Yes | E78: Broad fit | F78: The complaint alleges a fraudulent bankruptcy entry that cannot be removed. The fraudulent-record and deletion theme fits, although this is a public record rather than an opened account. | G78: I have tried numerous times to have a bankruptcy that is reporting on my file removed as it is not mine. The company reporting it to you is frozen to my personal information due to fraud. So how is it possible this wrong information is reporting on my credit report. This is my last attempt to have it removed or I will be taking … | H78: Fraudulent or unrecognized credit entries | I78: Online BERTopic cluster 11 | K78: 74 | L78: 112
A79: BERTopic | B79: B11 | C79: 1038397 | D79: Yes | E79: Clear fit | F79: The consumer disputes an account linked to a state where they never lived and cites fraud reports. Identity theft, fraudulent accounts and removal fit directly. | G79: A fraudulent account from is reporting on my credit. I did not live in the State of California in the year 2018. I live in the State of Louisiana. My address at the time this account was open was : , LA . Ive contacted both the creditor and credit bureaus providing ; FTC report and police report. Both creditor and bureaus are re … | H79: Fraudulent or unrecognized credit entries | I79: Online BERTopic cluster 11 | K79: 75 | L79: 113
... A103: BERTopic | B103: B9 | C103: 1044314 | D103: Yes | E103: Clear fit | F103: The consumer says bills falsely show arrears despite on-time agreed payments. The late-payment/status dispute fits even though the text focuses on billing rather than bureau reporting. | G103: From the onset of Realtime Resolutions has provided false and inaccurate billing statements. Despite paying the agreed amount on time Realtime Resolutions continues to send me billing which reflects that I am behind on payments which actually I am not. This is more than frustrating as this is the third complaint filed to have an … | H103: Late-payment and delinquency accuracy | I103: Online BERTopic cluster 9 | K103: 99 | L103: 163
A104: NMF | B104: N1 | C104: 778371 | D104: Yes | E104: Clear fit | F104: The consumer explicitly says information on their report is inaccurate. This supports the basic reporting-accuracy theme, although the complaint is very brief. | G104: this company on my report is reporting inaccurately. | H104: Credit-report accuracy and disputes | I104: NMF topic 1 | J104: 0.95715469 | K104: 100 | L104: 164
A105: NMF | B105: N1 | C105: 1013131 | D105: Yes | E105: Clear fit | F105: The consumer disputes an old or incorrect bankruptcy entry that bureaus retained. This directly fits inaccurate credit reporting and unresolved disputes. | G105: I have a Bankruptcy Chapter listed on my , and Equifax reports. I have not filed a Bankruptcy within the last 15 years. I have disputed this Bankruptcy which is appearing on my credit reports, and the credit bureaus have left this on my reports. | H105: Credit-report accuracy and disputes | I105: NMF topic 1 | J105: 0.94144887 | K105: 101 | L105: 137
A106: NMF | B106: N1 | C106: 1085744 | D106: Yes | E106: Clear fit | F106: The consumer requests correction of names and addresses on credit reports after providing documents. The reporting-accuracy and removal terms fit directly. | G106: I was just looking over my credit report and found some addresses that appear to be incorrect. I have already requested this information to be deleted and I have submitted documents showing my current address on / /. I still see incorrect addresses listed ( which I would like removed please ) : Incorrect Addresses : There should … | H106: Credit-report accuracy and disputes | I106: NMF topic 1 | J106: 0.93964428 | K106: 102 | L106: 165
A107: NMF | B107: N10 | C107: 386482 | D107: Yes | E107: Clear fit | F107: The consumer disputes a score drop after card balance transfers and allegedly missing payment updates. Both credit-card and credit-score terms fit the main issue. | G107: On / /2019 I was alerted to a negative change to my Transunion credit report resulting in a 91 point drop in my credit score. The negative report was that my balance on the Credit Card increased {$820.00}, but what Transunion is not considering is that I transferred that balance from my Credit Card. It was just a transfer, there … | H107: Credit cards, credit scores and reports | I107: NMF topic 10 | J107: 0.61361551 | K107: 103 | L107: 167
A108: NMF | B108: N10 | C108: 346231 | D108: Yes | E108: Broad fit | F108: The consumer says disputes about fraudulent credit cards were disregarded. The broad credit-card/report theme fits, but it does not separate fraud from other card problems. | G108: I have a couple of fraudulent credit cards that Ive told , and to dispute but they disregarded me wish dealing with my credit file. | H108: Credit cards, credit scores and reports | I108: NMF topic 10 | J108: 0.58188409 | K108: 104 | L108: 168
A109: NMF | B109: N10 | C109: 671815 | D109: Yes | E109: Broad fit | F109: The consumer cannot obtain an Equifax score online when needed for refinancing. The credit-score theme fits, although this is access/delivery rather than card billing. | G109: Today I accessed your site to get all three of my scores, for free. Equifax replied with " Onine Delivery Unavailable. '' # . I have to organize a bunch of documents to get my score, by snail mail? WHY? This is ANOTHER example of how the system is broken. I need the score TODAY to deal with an important refinancing decision. Ple … | H109: Credit cards, credit scores and reports | I109: NMF topic 10 | J109: 0.55665171 | K109: 105 | L109: 169
A110: NMF | B110: N11 | C110: 414284 | D110: Yes | E110: Clear fit | F110: The consumer disputes late-payment entries during a payment-relief period. This is a direct match to late-payment reporting and verification. | G110: There were not payment required from until / /2020 due the virus ; however, is showing late payments for andXX/ /2020. I was never late and I am requesting METHOD OF VERIFICATION AND PRECEDURED USED FOR VERIFICATION. PER MY RIGHT. | H110: Late-payment accuracy | I110: NMF topic 11 | J110: 0.70476329 | K110: 106 | L110: 170
A111: NMF | B111: N11 | C111: 285821 | D111: Yes | E111: Clear fit | F111: The statement explicitly denies the reported late payments. The late-payment topic fits directly, although no further details are supplied. | G111: THERE ARE LATE PAYMENTS ON MY ACCOUNT THAT ARE NOT ACCURATE I NEVER MADE A LATE PAYMENT | H111: Late-payment accuracy | I111: NMF topic 11 | J111: 0.65682387 | K111: 107 | L111: 48
A112: NMF | B112: N11 | C112: 932665 | D112: Yes | E112: Clear fit | F112: TransUnion allegedly still shows a late status after a late-payment entry was removed. The topic fits this remaining late-payment reporting error. | G112: was incorrectly reporting late payment for / / and I previously submitted a CPFB complaint regarding the handling of that dispute ( see attachment ) .The CPFB complaint was resolved and the company did remove the late payment from the payment history on my reports, however, on my transunion report the payment status is still sho … | H112: Late-payment accuracy | I112: NMF topic 11 | J112: 0.57270843 | K112: 108 | L112: 49
A113: NMF | B113: N12 | C113: 482755 | D113: Yes | E113: Clear fit | F113: The complaint lists disputed balances and opening dates and demands removal of unverified accounts. Those account-field and validation terms closely match N12. | G113: This is , who is submitting this CFPB complaint myself, and to inform you that there is no third party involved in the process. Regardless of the multiple written requests, the unverified accounts listed below are still reporting on my credit report in violation of federal law. The /Equifax Credit Bureaus failed to comply with t … | H113: Unverified accounts, balances and dates | I113: NMF topic 12 | J113: 0.67706913 | K113: 109 | L113: 86
A114: NMF | B114: N12 | C114: 641108 | D114: Yes | E114: Clear fit | F114: The consumer requests verification and deletion of remaining disputed accounts, listing balances. Validation, balances and erroneous credit entries fit directly. | G114: I am , and I appreciate your taking the time to delete some of the information in my credit file ; however, there are still other accounts that need to be corrected and deleted. The 3 credit bureaus must verify these accounts under Sections 609 ( a ) ( 1 ) ( A ) and 611 ( a ) ( 1 ). ( A ). I am hoping that these disputed account … | H114: Unverified accounts, balances and dates | I114: NMF topic 12 | J114: 0.62411994 | K114: 110 | L114: 171
...

Sheet Topics
A1: Topic meanings and limitations | B1: Topic meanings and limitations | C1: Topic meanings and limitations | D1: Topic meanings and limitations | E1: Topic meanings and limitations | F1: Topic meanings and limitations | G1: Topic meanings and limitations | H1: Topic meanings and limitations | I1: Topic meanings and limitations | J1: Topic meanings and limitations | K1: Topic meanings and limitations
A2: Topic IDs are local to each model. LSA labels are signed component poles. Review counts refer only to selected examples; held-out counts refer to the 1,000 assignment rows. | B2: Topic IDs are local to each model. LSA labels are signed component poles. Review counts refer only to selected examples; held-out counts refer to the 1,000 assignment rows. | C2: Topic IDs are local to each model. LSA labels are signed component poles. Review counts refer only to selected examples; held-out counts refer to the 1,000 assignment rows. | D2: Topic IDs are local to each model. LSA labels are signed component poles. Review counts refer only to selected examples; held-out counts refer to the 1,000 assignment rows. | E2: Topic IDs are local to each model. LSA labels are signed component poles. Review counts refer only to selected examples; held-out counts refer to the 1,000 assignment rows. | F2: Topic IDs are local to each model. LSA labels are signed component poles. Review counts refer only to selected examples; held-out counts refer to the 1,000 assignment rows. | G2: Topic IDs are local to each model. LSA labels are signed component poles. Review counts refer only to selected examples; held-out counts refer to the 1,000 assignment rows. | H2: Topic IDs are local to each model. LSA labels are signed component poles. Review counts refer only to selected examples; held-out counts refer to the 1,000 assignment rows. | I2: Topic IDs are local to each model. LSA labels are signed component poles. Review counts refer only to selected examples; held-out counts refer to the 1,000 assignment rows. | J2: Topic IDs are local to each model. LSA labels are signed component poles. Review counts refer only to selected examples; held-out counts refer to the 1,000 assignment rows. | K2: Topic IDs are local to each model. LSA labels are signed component poles. Review counts refer only to selected examples; held-out counts refer to the 1,000 assignment rows.
A4: Model | B4: Topic | C4: Interpreted theme | D4: Original top words | E4: Interpretation note | F4: Reviewed | G4: Yes | H4: No | I4: Unclear | J4: Held-out count | K4: Original model label
A5: LSA | B5: C1+ | C5: Credit reporting and account information (broad) | D5: account, credit, report, not, section, information, consumer, reporting, s, state, c, u | E5: Broad component; credit-reporting vocabulary occurs in many different complaint types. | F5: =COUNTIFS(Review!$A$5:$A$139,A5,Review!$B$5:$B$139,B5) -> 3 | G5: =COUNTIFS(Review!$A$5:$A$139,A5,Review!$B$5:$B$139,B5,Review!$D$5:$D$139,"Yes") -> 3 | H5: =COUNTIFS(Review!$A$5:$A$139,A5,Review!$B$5:$B$139,B5,Review!$D$5:$D$139,"No") -> 0 | I5: =COUNTIFS(Review!$A$5:$A$139,A5,Review!$B$5:$B$139,B5,Review!$D$5:$D$139,"Unclear") -> 0 | J5: 712 | K5: Component 1, + pole
A6: LSA | B6: C1- | C6: Uninterpretable concatenated tokens | D6: xxxxxxxxcontinuestofurnishinquiresonmycreditreport, xxxxxxxxaccountopeninmynameforxxxxdollars, youarerequiredtocomply, yourpaymentduedatewillnothaveanyalertwhatsoeverthatitislate, synchronydoesnotsendanynotificationsaboutpaymentduedates, xxxxxxxxxxxxamountxxxxxxxxdateopenedxxxx, xxxxandthereptriedtotransfermetothedepartmentthatsetupthepaymentandthecalldropped, shedidntmentionanythingaboutapaymentbeingscheduledforxxxxbutnowafullpaymentjustcameoutofmyaccount, whenwillthisloanbepaidoff, whereismymoneygoingandiwantthatxx, whatismybalance, sitemanager | E6: Keywords appear to include words joined together. No selected examples or held-out assignments for this pole. | F6: =COUNTIFS(Review!$A$5:$A$139,A6,Review!$B$5:$B$139,B6) -> 0 | G6: =COUNTIFS(Review!$A$5:$A$139,A6,Review!$B$5:$B$139,B6,Review!$D$5:$D$139,"Yes") -> 0 | H6: =COUNTIFS(Review!$A$5:$A$139,A6,Review!$B$5:$B$139,B6,Review!$D$5:$D$139,"No") -> 0 | I6: =COUNTIFS(Review!$A$5:$A$139,A6,Review!$B$5:$B$139,B6,Review!$D$5:$D$139,"Unclear") -> 0 | J6: 0 | K6: Component 1, - pole
A7: LSA | B7: C2+ | C7: FCRA privacy and written-consent template | D7: section, c, u, right, reporting, s, consumer, privacy, state, furnish, violate, instruction | E7: Primarily repeated statutory wording; a style/template topic. | F7: =COUNTIFS(Review!$A$5:$A$139,A7,Review!$B$5:$B$139,B7) -> 3 | G7: =COUNTIFS(Review!$A$5:$A$139,A7,Review!$B$5:$B$139,B7,Review!$D$5:$D$139,"Yes") -> 3 | H7: =COUNTIFS(Review!$A$5:$A$139,A7,Review!$B$5:$B$139,B7,Review!$D$5:$D$139,"No") -> 0 | I7: =COUNTIFS(Review!$A$5:$A$139,A7,Review!$B$5:$B$139,B7,Review!$D$5:$D$139,"Unclear") -> 0 | J7: 42 | K7: Component 2, + pole
A8: LSA | B8: C2- | C8: Reporting and loan/payment disputes (mixed) | D8: report, payment, not, credit, pay, loan, company, receive, send, tell, debt, remove | E8: Mixed negative pole; no selected examples or held-out assignments. | F8: =COUNTIFS(Review!$A$5:$A$139,A8,Review!$B$5:$B$139,B8) -> 0 | G8: =COUNTIFS(Review!$A$5:$A$139,A8,Review!$B$5:$B$139,B8,Review!$D$5:$D$139,"Yes") -> 0 | H8: =COUNTIFS(Review!$A$5:$A$139,A8,Review!$B$5:$B$139,B8,Review!$D$5:$D$139,"No") -> 0 | I8: =COUNTIFS(Review!$A$5:$A$139,A8,Review!$B$5:$B$139,B8,Review!$D$5:$D$139,"Unclear") -> 0 | J8: 0 | K8: Component 2, - pole
A9: LSA | B9: C3+ | C9: Credit-report corrections and identity theft | D9: report, credit, information, item, inquiry, remove, theft, identity, delete, inaccurate, bureau, file | E9: Reporting errors and fraudulent entries overlap in this component. | F9: =COUNTIFS(Review!$A$5:$A$139,A9,Review!$B$5:$B$139,B9) -> 3 | G9: =COUNTIFS(Review!$A$5:$A$139,A9,Review!$B$5:$B$139,B9,Review!$D$5:$D$139,"Yes") -> 3 | H9: =COUNTIFS(Review!$A$5:$A$139,A9,Review!$B$5:$B$139,B9,Review!$D$5:$D$139,"No") -> 0 | I9: =COUNTIFS(Review!$A$5:$A$139,A9,Review!$B$5:$B$139,B9,Review!$D$5:$D$139,"Unclear") -> 0 | J9: 7 | K9: Component 3, + pole
A10: LSA | B10: C3- | C10: Loan servicing and payment problems | D10: payment, loan, pay, bank, tell, card, make, late, mortgage, say, fee, charge | E10: Broad product scope, including mortgages and student loans. | F10: =COUNTIFS(Review!$A$5:$A$139,A10,Review!$B$5:$B$139,B10) -> 3 | G10: =COUNTIFS(Review!$A$5:$A$139,A10,Review!$B$5:$B$139,B10,Review!$D$5:$D$139,"Yes") -> 3 | H10: =COUNTIFS(Review!$A$5:$A$139,A10,Review!$B$5:$B$139,B10,Review!$D$5:$D$139,"No") -> 0 | I10: =COUNTIFS(Review!$A$5:$A$139,A10,Review!$B$5:$B$139,B10,Review!$D$5:$D$139,"Unclear") -> 0 | J10: 131 | K10: Component 3, - pole
A11: LSA | B11: C4+ | C11: Debt collection and validation | D11: debt, collection, letter, send, company, information, owe, consumer, validation, receive, request, provide | E11: Clear collection and proof-of-debt vocabulary. | F11: =COUNTIFS(Review!$A$5:$A$139,A11,Review!$B$5:$B$139,B11) -> 3 | G11: =COUNTIFS(Review!$A$5:$A$139,A11,Review!$B$5:$B$139,B11,Review!$D$5:$D$139,"Yes") -> 3 | H11: =COUNTIFS(Review!$A$5:$A$139,A11,Review!$B$5:$B$139,B11,Review!$D$5:$D$139,"No") -> 0 | I11: =COUNTIFS(Review!$A$5:$A$139,A11,Review!$B$5:$B$139,B11,Review!$D$5:$D$139,"Unclear") -> 0 | J11: 55 | K11: Component 4, + pole
A12: LSA | B12: C4- | C12: Account ownership, opening and closure | D12: account, open, inquiry, card, bank, theft, identity, fraudulent, balance, late, close, credit | E12: Fraud, balances and account-management issues overlap. | F12: =COUNTIFS(Review!$A$5:$A$139,A12,Review!$B$5:$B$139,B12) -> 3 | G12: =COUNTIFS(Review!$A$5:$A$139,A12,Review!$B$5:$B$139,B12,Review!$D$5:$D$139,"Yes") -> 3 | H12: =COUNTIFS(Review!$A$5:$A$139,A12,Review!$B$5:$B$139,B12,Review!$D$5:$D$139,"No") -> 0 | I12: =COUNTIFS(Review!$A$5:$A$139,A12,Review!$B$5:$B$139,B12,Review!$D$5:$D$139,"Unclear") -> 0 | J12: 7 | K12: Component 4, - pole
A13: LSA | B13: C5+ | C13: Fraudulent accounts and debts not owned | D13: account, debt, theft, identity, collection, open, victim, number, bank, fraudulent, money, owe | E13: Identity theft and debt ownership overlap. | F13: =COUNTIFS(Review!$A$5:$A$139,A13,Review!$B$5:$B$139,B13) -> 3 | G13: =COUNTIFS(Review!$A$5:$A$139,A13,Review!$B$5:$B$139,B13,Review!$D$5:$D$139,"Yes") -> 3 | H13: =COUNTIFS(Review!$A$5:$A$139,A13,Review!$B$5:$B$139,B13,Review!$D$5:$D$139,"No") -> 0 | I13: =COUNTIFS(Review!$A$5:$A$139,A13,Review!$B$5:$B$139,B13,Review!$D$5:$D$139,"Unclear") -> 0 | J13: 4 | K13: Component 5, + pole
A14: LSA | B14: C5- | C14: Late payments and credit-report accuracy | D14: payment, late, loan, inquiry, report, credit, day, inaccurate, mortgage, item, month, make | E14: Some broader loan/inquiry terms remain. | F14: =COUNTIFS(Review!$A$5:$A$139,A14,Review!$B$5:$B$139,B14) -> 3 | G14: =COUNTIFS(Review!$A$5:$A$139,A14,Review!$B$5:$B$139,B14,Review!$D$5:$D$139,"Yes") -> 3 | H14: =COUNTIFS(Review!$A$5:$A$139,A14,Review!$B$5:$B$139,B14,Review!$D$5:$D$139,"No") -> 0 | I14: =COUNTIFS(Review!$A$5:$A$139,A14,Review!$B$5:$B$139,B14,Review!$D$5:$D$139,"Unclear") -> 0 | J14: 13 | K14: Component 5, - pole
A15: LSA | B15: C6+ | C15: Account balances and reporting disputes | D15: account, late, report, dispute, collection, debt, bureau, balance, inaccurate, letter, credit, day | E15: Mixed positive pole; no selected examples or held-out assignments. | F15: =COUNTIFS(Review!$A$5:$A$139,A15,Review!$B$5:$B$139,B15) -> 0 | G15: =COUNTIFS(Review!$A$5:$A$139,A15,Review!$B$5:$B$139,B15,Review!$D$5:$D$139,"Yes") -> 0 | H15: =COUNTIFS(Review!$A$5:$A$139,A15,Review!$B$5:$B$139,B15,Review!$D$5:$D$139,"No") -> 0 | I15: =COUNTIFS(Review!$A$5:$A$139,A15,Review!$B$5:$B$139,B15,Review!$D$5:$D$139,"Unclear") -> 0 | J15: 0 | K15: Component 6, + pole
A16: LSA | B16: C6- | C16: Identity theft and unauthorized inquiries | D16: inquiry, theft, identity, victim, consumer, loan, block, hard, authorize, unauthorized, card, make | E16: Includes both fraud and inquiry-blocking complaints. | F16: =COUNTIFS(Review!$A$5:$A$139,A16,Review!$B$5:$B$139,B16) -> 3 | G16: =COUNTIFS(Review!$A$5:$A$139,A16,Review!$B$5:$B$139,B16,Review!$D$5:$D$139,"Yes") -> 3 | H16: =COUNTIFS(Review!$A$5:$A$139,A16,Review!$B$5:$B$139,B16,Review!$D$5:$D$139,"No") -> 0 | I16: =COUNTIFS(Review!$A$5:$A$139,A16,Review!$B$5:$B$139,B16,Review!$D$5:$D$139,"Unclear") -> 0 | J16: 29 | K16: Component 6, - pole
... A52: NMF | B52: N12 | C52: Unverified accounts, balances and dates | D52: balance, bureau, credit, date, validate, erroneous, law, item, original, open, unverified, owe | E52: Often captures field-list structure rather than the underlying cause. | F52: =COUNTIFS(Review!$A$5:$A$139,A52,Review!$B$5:$B$139,B52) -> 3 | G52: =COUNTIFS(Review!$A$5:$A$139,A52,Review!$B$5:$B$139,B52,Review!$D$5:$D$139,"Yes") -> 3 | H52: =COUNTIFS(Review!$A$5:$A$139,A52,Review!$B$5:$B$139,B52,Review!$D$5:$D$139,"No") -> 0 | I52: =COUNTIFS(Review!$A$5:$A$139,A52,Review!$B$5:$B$139,B52,Review!$D$5:$D$139,"Unclear") -> 0 | J52: 21 | K52: NMF topic 12

Sheet Complaints
A1: Full supplied complaint texts | B1: Full supplied complaint texts | C1: Full supplied complaint texts | D1: Full supplied complaint texts | E1: Full supplied complaint texts
A2: 118 complaint IDs • Full supplied wording, including redactions, spelling and legal assertions, is preserved. | B2: 118 complaint IDs • Full supplied wording, including redactions, spelling and legal assertions, is preserved. | C2: 118 complaint IDs • Full supplied wording, including redactions, spelling and legal assertions, is preserved. | D2: 118 complaint IDs • Full supplied wording, including redactions, spelling and legal assertions, is preserved. | E2: 118 complaint IDs • Full supplied wording, including redactions, spelling and legal assertions, is preserved.
A3: Long texts are split into consecutive parts for readability. Join the text parts in order with no added characters to reconstruct a complaint. Legal assertions are not checked by this review. | B3: Long texts are split into consecutive parts for readability. Join the text parts in order with no added characters to reconstruct a complaint. Legal assertions are not checked by this review. | C3: Long texts are split into consecutive parts for readability. Join the text parts in order with no added characters to reconstruct a complaint. Legal assertions are not checked by this review. | D3: Long texts are split into consecutive parts for readability. Join the text parts in order with no added characters to reconstruct a complaint. Legal assertions are not checked by this review. | E3: Long texts are split into consecutive parts for readability. Join the text parts in order with no added characters to reconstruct a complaint. Legal assertions are not checked by this review.
A5: Document ID | B5: Part | C5: Parts | D5: Complaint text — continuation parts preserve original spacing | E5: Review row IDs
A6: 1238069 | B6: 1 | C6: 7 | D6: Hi I am submitting this this is not any influence and this is not a third party. has low and unfair credit number for me in their report. I have complained more than 88 times nonstop this is exhausting im they are not putting these fraudulent inquiries in dispute and accounts and they still have not deleted them either I am depressed. The problem has not been resolved. my fico has me at a credit score over 709 has me at a score around 590. That is a huge difference. paints me as a . my fico say I have good credit. What the heck is going on here. i have almost no debt and my identity was stolen causing my score to drop n i made this clear for 90 days straight with i spoke to a representative agent name from the fraud department I prefer to speak to a us rept but they refused they had me on mute for 4 hours which was hurtful I have a | E6: 1
A7: 1238069 | B7: 2 | C7: 7 | D7: perfect repayment record. I have very low credit utilization. I have one negative credit items outstanding debt now that is not mines. I have modest but ok income. Social Security. Something is wrong with . I do not understand why they are abusing consumers they do not help you at all This was a first step towards attempting resolution. They kept lying telling me they disputed n its not reporting but it keep reporting this inaccurate information without my authorization. They refused or were unable to verify n remove the inquiries and negative account its been 60days n they record the calls n admitted they had my police report ftc and affidavit That was after attempting to contact more than 88 times in the last 120 days. is an abusive company. They are supposed to be protecting consumers. They need to be reigned in. they are causing me | E7: 1
A8: 1238069 | B8: 3 | C8: 7 | D8: severe and stopping me from getting this job offer n now im homeless n cant provide to my PLEASE HELP ME PLEASE im now.with no help they keep ignoring me after I keep telling them repeatedly they are hurting my character of my name they will not respond and it not even in investigation with and me and my son are bout to be homeless please help I cant live like this The credit bureaus never did a proper " investigation '' according to the FCRA. Section 1681a of the Fair Credit Reporting Act defines an investigative consumer report as a consumer report or portion thereof in which information on a consumer 's character, general reputation, personal characteristics, or mode of living is obtained through personal interviews with neighbors, friends, or associates of the consumer reported on or with others with whom he is acquainted or who may | E8: 1
A9: 1238069 | B9: 4 | C9: 7 | D9: have knowledge concerning any such items of information. They did not do this. Also they have violated my rights even more. The credit bureaus stated my account was properly investigated but how is that possible if I never gave these creditors WRITTEN CONSENT OR AUTHORIZATION TO USE MY PERSONAL INFORMATION TO OPEN OR CLOSE ANY ACCOUNT. THESE BALANCES IS IN ACCURATE, PAYMENT STATUS AND HISTORY IN ACCURATE, LAST ACTIVITY DATE IS IN ACCURATE, ALL INFORMATION REGARDING THESE NEGATIVE INSTALLMENT LOAN IS INACCURATE.Someone is using my personal information pretending to be me to obtain credit. I do not know anything about this fraudulent account. I do not have any closed OR OPEN accounts with THESE LISTED CREDITORS BELOW WITH MY DOCUMENTATION. Also they have violated my rights even more In accordance with the Fair Credit Reporting Everything | E9: 1
A10: 1238069 | B10: 5 | C10: 7 | D10: has to be 100 % accurate on my credit report. The credit bureaus stated it was properly investigated but how is that even possible if THESE CREDITORS DID NOT GET ANY WRITTEN SIGNATURE, CONSENT OR AUTHORIZATION FROM ME. This account is fraud and does not belong to me, this is in accurate, I have never opened or closed any account with THESE CREDITORS I ask for documents with signature or authorization, they did not submit my request.This grounds for removal and deletion immediately. I never gave THESE CREDITORS ANY WRITTEN CONSENT OR AUTHORIZATION TO USE MY PERSONAL INFORMATION TO OPEN THIS ACCOUNT. THIS IS FRAUD. I have ASK FOR SIGNED DOCUMENTS WITH MY SIGNATURE GIVING WRITTEN CONSENT TO OPEN THIS FRAUDULENT CREDIT ACCOUNTS. SOMEONE USE MY PERSONAL INFORMATION PRETENDING TO BE ME WITHOUT MY AUTHORIZATION OR CONSENT TO OPEN OR CLOSE ANY | E10: 1
A11: 1238069 | B11: 6 | C11: 7 | D11: CREDIT ACCOUNT WITH THESE CREDITORS BELOW They also violated the law because according to 15 U.S.C 1681 section 602 A. states i have the rights to privacy 15 U.S.C 1681 section 604 section 2 : it also states a consumer reporting agency can not furnish a account without my written consent. In accordance with the Fair Credit Reporting act WITH THESE CREDITORS BELOW EQUIFAX AND AND has violated my rights. 15 U.S.C 1681 section 602 A. States I have the right to privacy. 15 U.S.C 1681 Section 604 A Section 2 : It also states a consumer reporting agency can not furnish a account without my written instructions 15 U.S.C 1666B : A creditor may not treat a payment on a credit card account under an open end consumer credit plan as late for any purpose SECTION 604 15 U.S CODE 1681 B THE LAW STATES THAT NO ONE CAN FURNISH INFORMATION ON MY CREDIT | E11: 1
A12: 1238069 | B12: 7 | C12: 7 | D12: REPORT WITHOUT MY CONSENT. SECTION 605 A 15 U.S CODE 1681 C-1 WITH NO WRITTEN CONSENT OR INSTRUCTIONS THAT WOULD IN FACT BE IDENTITY THEFT SECTION 605 B 15 U.S CODE 1681C A copy of section 605B of the Fair Credit Reporting Act, whichrequires you to block the.fraudulent information on my credit report resulting from identity theft within four business days and to promptly notify the furnisher ( s ) of that information. Please block this information from my credit report, pursuant to section 605B of the Fair Credit Reporting Act, and send the required notifications to all furnishers of thisinformation. | E12: 1
